Workbook

Sheet Planilha2
A3: Data | B3: Tentativas | C3: Conversões
A4: 20/04/2026 | B4: 291 | C4: 48
A5: 22/04/2026 | B5: 1846 | C5: 43
A6: 24/04/2026 | B6: 724 | C6: 9
A7: 26/05/2026 | B7: 164 | C7: 28
A8: 27/05/2026 | B8: 106 | C8: 6
A9: 28/05/2026 | B9: 94 | C9: 6
A10: Total Geral | B10: 3225 | C10: 140

Sheet chamadas_22-04-2026_165407
A1: DATA | B1: FILA | C1: AGENTE | D1: IDCRM | E1: DOC | F1: IDDISCADOR | G1: UNIQUEID | H1: ORIGEM | I1: DESTINO | J1: TIPO | K1: STATUS | L1: STATUS_NEGOCIO | M1: MAILING | N1: DESLIGADOPOR | O1: ISDN_CODE | P1: AGENDAMENTO | Q1: CPF/CNPJ COLETADO | R1: TEMPO_CONECTADO | S1: TEMPO_DE_CONVERSACAO | T1: Interessado | U1: Data2
A2: 46132.386 | B2: 3003 - FirjanAtivo | C2: 6052-Marcia Lima Peixoto | D2: 1 | E2: 1 | F2: 1 | G2: 17766873544641 | H2: (21) 97424-1466 | I2: 3003 | J2: Discador | K2: Atendido | L2: Engano | M2: BPATIVO20042026 | N2: Cliente | O2: 16 | R2: 0.00021990741 | S2: 0.00018518519 | T2: =IF(Tabela1[[#This Row],[STATUS_NEGOCIO]]="Enviar E-mail",1,"") | U2: =TEXT(Tabela1[[#This Row],[DATA]],"dd/mm/aaaa") -> 20/04/2026
A3: 46132.399 | B3: 3003 - FirjanAtivo | C3: 6044-Roseli Honorato Dos Santos | F3: 2761431712 | G3: 17766884936461 | H3: (21) 98474-3198 | I3: (21) 2038-4382 | J3: Sainte | K3: Atendido | L3: Fora de Area / Cx de Mensagens | N3: Agente | O3: 16 | R3: 0.00074074074 | S3: 0.00048611111 | T3: =IF(Tabela1[[#This Row],[STATUS_NEGOCIO]]="Enviar E-mail",1,"") | U3: =TEXT(Tabela1[[#This Row],[DATA]],"dd/mm/aaaa") -> 20/04/2026
A4: 46132.4 | B4: 3003 - FirjanAtivo | C4: 6052-Marcia Lima Peixoto | F4: 2776525487 | G4: 17766885176521 | H4: (21) 99983-6949 | I4: (21) 2038-4382 | J4: Sainte | K4: Atendido | L4: Engano | N4: Agente | O4: 16 | R4: 0.000625 | S4: 0.00030092593 | T4: =IF(Tabela1[[#This Row],[STATUS_NEGOCIO]]="Enviar E-mail",1,"") | U4: =TEXT(Tabela1[[#This Row],[DATA]],"dd/mm/aaaa") -> 20/04/2026
A5: 46132.401 | B5: 3003 - FirjanAtivo | C5: 6044-Roseli Honorato Dos Santos | F5: 2774907115 | G5: 17766886376691 | H5: (24) 99821-8454 | I5: (21) 2038-4382 | J5: Sainte | K5: Atendido | L5: Fora de Area / Cx de Mensagens | N5: Agente | O5: 16 | R5: 0.000625 | S5: 0.00019675926 | T5: =IF(Tabela1[[#This Row],[STATUS_NEGOCIO]]="Enviar E-mail",1,"") | U5: =TEXT(Tabela1[[#This Row],[DATA]],"dd/mm/aaaa") -> 20/04/2026
A6: 46132.401 | B6: 3003 - FirjanAtivo | C6: 6052-Marcia Lima Peixoto | F6: 2746674497 | G6: 17766886446711 | H6: (21) 96998-5832 | I6: (21) 2038-4382 | J6: Sainte | K6: Atendido | L6: Engano | N6: Agente | O6: 16 | R6: 0.00025462963 | S6: 0.00015046296 | T6: =IF(Tabela1[[#This Row],[STATUS_NEGOCIO]]="Enviar E-mail",1,"") | U6: =TEXT(Tabela1[[#This Row],[DATA]],"dd/mm/aaaa") -> 20/04/2026
A7: 46132.402 | B7: 3003 - FirjanAtivo | C7: 6052-Marcia Lima Peixoto | F7: 2776525684 | G7: 17766887146851 | H7: (21) 99983-6949 | I7: (21) 2038-4382 | J7: Sainte | K7: Não Atendeu | L7: Não Atendeu | N7: Agente | O7: 19 | R7: 0.0002662037 | S7: --- | T7: =IF(Tabela1[[#This Row],[STATUS_NEGOCIO]]="Enviar E-mail",1,"") | U7: =TEXT(Tabela1[[#This Row],[DATA]],"dd/mm/aaaa") -> 20/04/2026
A8: 46132.402 | B8: 3003 - FirjanAtivo | C8: 6044-Roseli Honorato Dos Santos | F8: 2776520152 | G8: 17766887276871 | H8: (22) 99983-1403 | I8: (21) 2038-4382 | J8: Sainte | K8: Atendido | L8: Fora de Area / Cx de Mensagens | N8: Agente | O8: 16 | R8: 0.00047453704 | S8: 5.787037e-05 | T8: =IF(Tabela1[[#This Row],[STATUS_NEGOCIO]]="Enviar E-mail",1,"") | U8: =TEXT(Tabela1[[#This Row],[DATA]],"dd/mm/aaaa") -> 20/04/2026
A9: 46132.403 | B9: 3003 - FirjanAtivo | C9: 6052-Marcia Lima Peixoto | F9: 2764934899 | G9: 17766888587201 | H9: (22) 98824-6019 | I9: (21) 2038-4382 | J9: Sainte | K9: Atendido | L9: Enviar E-mail | N9: Agente | O9: 16 | R9: 0.0023032407 | S9: 0.0022453704 | T9: =IF(Tabela1[[#This Row],[STATUS_NEGOCIO]]="Enviar E-mail",1,"") -> 1 | U9: =TEXT(Tabela1[[#This Row],[DATA]],"dd/mm/aaaa") -> 20/04/2026
A10: 46132.405 | B10: 3003 - FirjanAtivo | C10: 6044-Roseli Honorato Dos Santos | F10: 2774938445 | G10: 17766890307491 | H10: (22) 99824-9393 | I10: (21) 2038-4382 | J10: Sainte | K10: Atendido | L10: Fora de Area / Cx de Mensagens | N10: Agente | O10: 16 | R10: 0.00053240741 | S10: 0.00010416667 | T10: =IF(Tabela1[[#This Row],[STATUS_NEGOCIO]]="Enviar E-mail",1,"") | U10: =TEXT(Tabela1[[#This Row],[DATA]],"dd/mm/aaaa") -> 20/04/2026
A11: 46132.406 | B11: 3003 - FirjanAtivo | C11: 6044-Roseli Honorato Dos Santos | F11: 2758422530 | G11: 17766891097531 | H11: (21) 98173-3400 | I11: (21) 2038-4382 | J11: Sainte | K11: Atendido | L11: Enviar E-mail | N11: Agente | O11: 16 | R11: 0.0017476852 | S11: 0.0016782407 | T11: =IF(Tabela1[[#This Row],[STATUS_NEGOCIO]]="Enviar E-mail",1,"") -> 1 | U11: =TEXT(Tabela1[[#This Row],[DATA]],"dd/mm/aaaa") -> 20/04/2026
A12: 46132.408 | B12: 3003 - FirjanAtivo | C12: 6052-Marcia Lima Peixoto | F12: 2776093403 | G12: 17766892637691 | H12: (22) 99940-4118 | I12: (21) 2038-4382 | J12: Sainte | K12: Não Atendeu | L12: Não Atendeu | N12: Agente | O12: 19 | R12: 0.00041666667 | S12: --- | T12: =IF(Tabela1[[#This Row],[STATUS_NEGOCIO]]="Enviar E-mail",1,"") | U12: =TEXT(Tabela1[[#This Row],[DATA]],"dd/mm/aaaa") -> 20/04/2026
A13: 46132.409 | B13: 3003 - FirjanAtivo | C13: 6052-Marcia Lima Peixoto | F13: 2776093453 | G13: 17766893137721 | H13: (22) 99940-4118 | I13: (21) 2038-4382 | J13: Sainte | K13: Atendido | L13: Tel Não Atende / Ocupado | N13: Agente | O13: 16 | R13: 0.00052083333 | S13: 9.2592593e-05 | T13: =IF(Tabela1[[#This Row],[STATUS_NEGOCIO]]="Enviar E-mail",1,"") | U13: =TEXT(Tabela1[[#This Row],[DATA]],"dd/mm/aaaa") -> 20/04/2026
A14: 46132.41 | B14: 3003 - FirjanAtivo | C14: 6052-Marcia Lima Peixoto | F14: 2774100613 | G14: 17766893897931 | H14: (22) 99741-1201 | I14: (21) 2038-4382 | J14: Sainte | K14: Não Atendeu | L14: Não Atendeu | N14: Agente | O14: 19 | R14: 0.0002662037 | S14: --- | T14: =IF(Tabela1[[#This Row],[STATUS_NEGOCIO]]="Enviar E-mail",1,"") | U14: =TEXT(Tabela1[[#This Row],[DATA]],"dd/mm/aaaa") -> 20/04/2026
A15: 46132.411 | B15: 3003 - FirjanAtivo | C15: 6044-Roseli Honorato Dos Santos | F15: 2769608750 | G15: 17766894748151 | H15: (24) 99291-9252 | I15: (21) 2038-4382 | J15: Sainte | K15: Atendido | L15: Fora de Area / Cx de Mensagens | N15: Agente | O15: 16 | R15: 0.00049768519 | S15: 8.1018519e-05 | T15: =IF(Tabela1[[#This Row],[STATUS_NEGOCIO]]="Enviar E-mail",1,"") | U15: =TEXT(Tabela1[[#This Row],[DATA]],"dd/mm/aaaa") -> 20/04/2026
A16: 46132.411 | B16: 3003 - FirjanAtivo | C16: 6052-Marcia Lima Peixoto | F16: 2774100700 | G16: 17766894778181 | H16: (22) 99741-1201 | I16: (21) 2038-4382 | J16: Sainte | K16: Não Atendeu | L16: Não Atendeu | N16: Agente | O16: 19 | R16: 0.00019675926 | S16: --- | T16: =IF(Tabela1[[#This Row],[STATUS_NEGOCIO]]="Enviar E-mail",1,"") | U16: =TEXT(Tabela1[[#This Row],[DATA]],"dd/mm/aaaa") -> 20/04/2026
A17: 46132.413 | B17: 3003 - FirjanAtivo | C17: 6044-Roseli Honorato Dos Santos | F17: 2764931219 | G17: 17766896838341 | H17: (24) 98824-1512 | I17: (21) 2038-4382 | J17: Sainte | K17: Atendido | L17: Fora de Area / Cx de Mensagens | N17: Agente | O17: 16 | R17: 0.00055555556 | S17: 0.00010416667 | T17: =IF(Tabela1[[#This Row],[STATUS_NEGOCIO]]="Enviar E-mail",1,"") | U17: =TEXT(Tabela1[[#This Row],[DATA]],"dd/mm/aaaa") -> 20/04/2026
A18: 46132.414 | B18: 3003 - FirjanAtivo | C18: 6044-Roseli Honorato Dos Santos | F18: 2776331224 | G18: 17766897818731 | H18: (22) 99964-1421 | I18: (21) 2038-4382 | J18: Sainte | K18: Atendido | L18: Fora de Area / Cx de Mensagens | N18: Cliente | O18: 16 | R18: 0.0003125 | S18: 0.00011574074 | T18: =IF(Tabela1[[#This Row],[STATUS_NEGOCIO]]="Enviar E-mail",1,"") | U18: =TEXT(Tabela1[[#This Row],[DATA]],"dd/mm/aaaa") -> 20/04/2026
A19: 46132.415 | B19: 3003 - FirjanAtivo | C19: 6044-Roseli Honorato Dos Santos | F19: 2776521263 | G19: 17766898378861 | H19: (22) 99983-1403 | I19: (21) 2038-4382 | J19: Sainte | K19: Atendido | L19: Tel Não Atende / Ocupado | N19: Cliente | O19: 16 | R19: 0.00053240741 | S19: 0.00011574074 | T19: =IF(Tabela1[[#This Row],[STATUS_NEGOCIO]]="Enviar E-mail",1,"") | U19: =TEXT(Tabela1[[#This Row],[DATA]],"dd/mm/aaaa") -> 20/04/2026
A20: 46132.416 | B20: 3003 - FirjanAtivo | C20: 6044-Roseli Honorato Dos Santos | F20: 2761471803 | G20: 17766899289071 | H20: (21) 98478-1854 | I20: (21) 2038-4382 | J20: Sainte | K20: Atendido | L20: Tel Não Atende / Ocupado | N20: Cliente | O20: 16 | R20: 0.00025462963 | S20: 0.00015046296 | T20: =IF(Tabela1[[#This Row],[STATUS_NEGOCIO]]="Enviar E-mail",1,"") | U20: =TEXT(Tabela1[[#This Row],[DATA]],"dd/mm/aaaa") -> 20/04/2026
A21: 46132.417 | B21: 3003 - FirjanAtivo | C21: 6044-Roseli Honorato Dos Santos | F21: 2761471871 | G21: 17766899969171 | H21: (21) 98478-1854 | I21: (21) 2038-4382 | J21: Sainte | K21: Atendido | L21: Tel Não Atende / Ocupado | N21: Cliente | O21: 16 | R21: 0.00034722222 | S21: 0.00028935185 | T21: =IF(Tabela1[[#This Row],[STATUS_NEGOCIO]]="Enviar E-mail",1,"") | U21: =TEXT(Tabela1[[#This Row],[DATA]],"dd/mm/aaaa") -> 20/04/2026
A22: 46132.387 | B22: 3003 - FirjanAtivo | C22: --- | D22: renataalvarengasilvagmailcom | E22: 59407605000144 | F22: 2 | G22: 17766873834671 | H22: (22) 99983-1403 | I22: 3003 | J22: Discador | K22: Atendido | L22: Fora de Area / Cx de Mensagens | M22: BPATIVO20042026 | N22: Agente | O22: 131 | R22: 0.00069444444 | S22: --- | T22: =IF(Tabela1[[#This Row],[STATUS_NEGOCIO]]="Enviar E-mail",1,"") | U22: =TEXT(Tabela1[[#This Row],[DATA]],"dd/mm/aaaa") -> 20/04/2026
A23: 46132.387 | B23: 3003 - FirjanAtivo | C23: --- | D23: comercialdegustogmailcom | E23: 23884500000139 | F23: 3 | G23: 17766874805171 | H23: (24) 98824-1512 | I23: Falha | J23: Discador | K23: Não Atendeu | L23: Não Atendeu | M23: BPATIVO20042026 | N23: -- | O23: 19 | R23: 0 | S23: --- | T23: =IF(Tabela1[[#This Row],[STATUS_NEGOCIO]]="Enviar E-mail",1,"") | U23: =TEXT(Tabela1[[#This Row],[DATA]],"dd/mm/aaaa") -> 20/04/2026
A24: 46132.404 | B24: 3003 - FirjanAtivo | C24: --- | D24: janayravisgueiracostagmaicom | E24: 24265410000122 | F24: 5 | G24: 17766888247081 | H24: (21) 99860-2307 | I24: 3003 | J24: Discador | K24: Atendido | L24: Fora de Area / Cx de Mensagens | M24: BPATIVO20042026 | N24: Agente | O24: 131 | R24: 0.00069444444 | S24: --- | T24: =IF(Tabela1[[#This Row],[STATUS_NEGOCIO]]="Enviar E-mail",1,"") | U24: =TEXT(Tabela1[[#This Row],[DATA]],"dd/mm/aaaa") -> 20/04/2026
A25: 46132.404 | B25: 3003 - FirjanAtivo | C25: --- | D25: aetaetsolutionscombr | E25: 9082639000138 | F25: 4 | G25: 17766888247071 | H25: (22) 99824-9393 | I25: 3003 | J25: Discador | K25: Atendido | L25: Fora de Area / Cx de Mensagens | M25: BPATIVO20042026 | N25: Agente | O25: 131 | R25: 0.00072916667 | S25: --- | T25: =IF(Tabela1[[#This Row],[STATUS_NEGOCIO]]="Enviar E-mail",1,"") | U25: =TEXT(Tabela1[[#This Row],[DATA]],"dd/mm/aaaa") -> 20/04/2026
A26: 46132.418 | B26: 3003 - FirjanAtivo | C26: 6044-Roseli Honorato Dos Santos | F26: 2761471956 | G26: 17766900819411 | H26: (21) 98478-1854 | I26: (21) 2038-4382 | J26: Sainte | K26: Atendido | L26: Fora de Area / Cx de Mensagens | N26: Agente | O26: 16 | R26: 0.00050925926 | S26: 9.2592593e-05 | T26: =IF(Tabela1[[#This Row],[STATUS_NEGOCIO]]="Enviar E-mail",1,"") | U26: =TEXT(Tabela1[[#This Row],[DATA]],"dd/mm/aaaa") -> 20/04/2026
A27: 46132.418 | B27: 3003 - FirjanAtivo | C27: 6044-Roseli Honorato Dos Santos | F27: 2776244273 | G27: 17766901449631 | H27: (21) 99955-4108 | I27: (21) 2038-4382 | J27: Sainte | K27: Atendido | L27: Fora de Area / Cx de Mensagens | N27: Cliente | O27: 16 | R27: 0.00023148148 | S27: 0.00011574074 | T27: =IF(Tabela1[[#This Row],[STATUS_NEGOCIO]]="Enviar E-mail",1,"") | U27: =TEXT(Tabela1[[#This Row],[DATA]],"dd/mm/aaaa") -> 20/04/2026
A28: 46132.419 | B28: 3003 - FirjanAtivo | C28: 6044-Roseli Honorato Dos Santos | F28: 2776687681 | G28: 177669019110001 | H28: (24) 99999-7466 | I28: (21) 2038-4382 | J28: Sainte | K28: Atendido | L28: Fora de Area / Cx de Mensagens | N28: Agente | O28: 16 | R28: 0.00021990741 | S28: 0.00018518519 | T28: =IF(Tabela1[[#This Row],[STATUS_NEGOCIO]]="Enviar E-mail",1,"") | U28: =TEXT(Tabela1[[#This Row],[DATA]],"dd/mm/aaaa") -> 20/04/2026
A29: 46132.419 | B29: 3003 - FirjanAtivo | C29: 6044-Roseli Honorato Dos Santos | F29: 2741230892 | G29: 177669023010181 | H29: (21) 96454-0641 | I29: (21) 2038-4382 | J29: Sainte | K29: Atendido | L29: Enviar E-mail | N29: Cliente | O29: 16 | R29: 0.0022453704 | S29: 0.0021643519 | T29: =IF(Tabela1[[#This Row],[STATUS_NEGOCIO]]="Enviar E-mail",1,"") -> 1 | U29: =TEXT(Tabela1[[#This Row],[DATA]],"dd/mm/aaaa") -> 20/04/2026
A30: 46132.422 | B30: 3003 - FirjanAtivo | C30: 6044-Roseli Honorato Dos Santos | F30: 2740876819 | G30: 177669045810761 | H30: (21) 96418-6340 | I30: (21) 2038-4382 | J30: Sainte | K30: Atendido | L30: Tel Não Atende / Ocupado | N30: Agente | O30: 16 | R30: 0.00071759259 | S30: 0.00028935185 | T30: =IF(Tabela1[[#This Row],[STATUS_NEGOCIO]]="Enviar E-mail",1,"") | U30: =TEXT(Tabela1[[#This Row],[DATA]],"dd/mm/aaaa") -> 20/04/2026
A31: 46132.422 | B31: 3003 - FirjanAtivo | C31: 6052-Marcia Lima Peixoto | F31: 2776094641 | G31: 177669050110781 | H31: (22) 99940-4118 | I31: (21) 2038-4382 | J31: Sainte | K31: Atendido | L31: Tel Não Atende / Ocupado | N31: Agente | O31: 16 | R31: 0.00049768519 | S31: 3.4722222e-05 | T31: =IF(Tabela1[[#This Row],[STATUS_NEGOCIO]]="Enviar E-mail",1,"") | U31: =TEXT(Tabela1[[#This Row],[DATA]],"dd/mm/aaaa") -> 20/04/2026
A32: 46132.423 | B32: 3003 - FirjanAtivo | C32: 6044-Roseli Honorato Dos Santos | F32: 2758123621 | G32: 177669055410981 | H32: (24) 98143-3043 | I32: (21) 2038-4382 | J32: Sainte | K32: Atendido | L32: Enviar E-mail | N32: Cliente | O32: 16 | R32: 0.001712963 | S32: 0.001400463 | T32: =IF(Tabela1[[#This Row],[STATUS_NEGOCIO]]="Enviar E-mail",1,"") -> 1 | U32: =TEXT(Tabela1[[#This Row],[DATA]],"dd/mm/aaaa") -> 20/04/2026
A33: 46132.423 | B33: 3003 - FirjanAtivo | C33: 6052-Marcia Lima Peixoto | F33: 2774101782 | G33: 177669055911101 | H33: (22) 99741-1201 | I33: (21) 2038-4382 | J33: Sainte | K33: Não Atendeu | L33: Não Atendeu | N33: Agente | O33: 19 | R33: 0.0002662037 | S33: --- | T33: =IF(Tabela1[[#This Row],[STATUS_NEGOCIO]]="Enviar E-mail",1,"") | U33: =TEXT(Tabela1[[#This Row],[DATA]],"dd/mm/aaaa") -> 20/04/2026
A34: 46132.424 | B34: 3003 - FirjanAtivo | C34: 6052-Marcia Lima Peixoto | F34: 2774101819 | G34: 177669059611191 | H34: (22) 99741-1201 | I34: (21) 2038-4382 | J34: Sainte | K34: Não Atendeu | L34: Não Atendeu | N34: Agente | O34: 19 | R34: 0.00043981481 | S34: --- | T34: =IF(Tabela1[[#This Row],[STATUS_NEGOCIO]]="Enviar E-mail",1,"") | U34: =TEXT(Tabela1[[#This Row],[DATA]],"dd/mm/aaaa") -> 20/04/2026
A35: 46132.431 | B35: 3003 - FirjanAtivo | C35: 6044-Roseli Honorato Dos Santos | F35: 2758124266 | G35: 177669119913681 | H35: (24) 98143-3043 | I35: (21) 2038-4382 | J35: Sainte | K35: Ocupado | L35: Ocupado | N35: Cliente | O35: 19 | R35: 1.1574074e-05 | S35: --- | T35: =IF(Tabela1[[#This Row],[STATUS_NEGOCIO]]="Enviar E-mail",1,"") | U35: =TEXT(Tabela1[[#This Row],[DATA]],"dd/mm/aaaa") -> 20/04/2026
A36: 46132.432 | B36: 3003 - FirjanAtivo | C36: 6044-Roseli Honorato Dos Santos | F36: 2758124354 | G36: 177669128713841 | H36: (24) 98143-3043 | I36: (21) 2038-4382 | J36: Sainte | K36: Ocupado | L36: Ocupado | N36: Cliente | O36: 19 | R36: 1.1574074e-05 | S36: --- | T36: =IF(Tabela1[[#This Row],[STATUS_NEGOCIO]]="Enviar E-mail",1,"") | U36: =TEXT(Tabela1[[#This Row],[DATA]],"dd/mm/aaaa") -> 20/04/2026
A37: 46132.432 | B37: 3003 - FirjanAtivo | C37: 6044-Roseli Honorato Dos Santos | F37: 2758124434 | G37: 177669136713991 | H37: (24) 98143-3043 | I37: (21) 2038-4382 | J37: Sainte | K37: Atendido | L37: Enviar E-mail | N37: Agente | O37: 16 | R37: 0.00025462963 | S37: 0.00017361111 | T37: =IF(Tabela1[[#This Row],[STATUS_NEGOCIO]]="Enviar E-mail",1,"") -> 1 | U37: =TEXT(Tabela1[[#This Row],[DATA]],"dd/mm/aaaa") -> 20/04/2026
A38: 46132.433 | B38: 3003 - FirjanAtivo | C38: 6044-Roseli Honorato Dos Santos | F38: 2774428717 | G38: 177669141314021 | H38: (22) 99773-7282 | I38: (21) 2038-4382 | J38: Sainte | K38: Atendido | L38: Fora de Area / Cx de Mensagens | N38: Cliente | O38: 16 | R38: 8.1018519e-05 | S38: 4.6296296e-05 | T38: =IF(Tabela1[[#This Row],[STATUS_NEGOCIO]]="Enviar E-mail",1,"") | U38: =TEXT(Tabela1[[#This Row],[DATA]],"dd/mm/aaaa") -> 20/04/2026
A39: 46132.435 | B39: 3003 - FirjanAtivo | C39: 6044-Roseli Honorato Dos Santos | F39: 2774428899 | G39: 177669159414341 | H39: (22) 99773-7282 | I39: (21) 2038-4382 | J39: Sainte | K39: Atendido | L39: Fora de Area / Cx de Mensagens | N39: Cliente | O39: 16 | R39: 0.00039351852 | S39: 4.6296296e-05 | T39: =IF(Tabela1[[#This Row],[STATUS_NEGOCIO]]="Enviar E-mail",1,"") | U39: =TEXT(Tabela1[[#This Row],[DATA]],"dd/mm/aaaa") -> 20/04/2026
A40: 46132.437 | B40: 3003 - FirjanAtivo | C40: 6044-Roseli Honorato Dos Santos | F40: 2758401836 | G40: 177669172614761 | H40: (22) 98171-0088 | I40: (21) 2038-4382 | J40: Sainte | K40: Atendido | L40: Fora de Area / Cx de Mensagens | N40: Agente | O40: 16 | R40: 0.00039351852 | S40: 0.00012731481 | T40: =IF(Tabela1[[#This Row],[STATUS_NEGOCIO]]="Enviar E-mail",1,"") | U40: =TEXT(Tabela1[[#This Row],[DATA]],"dd/mm/aaaa") -> 20/04/2026
...

Sheet Planilha1
A1: STATUS_NEGOCIO | B1: Retorno | C1: QTD | E1: Retorno | F1: QTD
A2: Engano | B2: Alo | C2: =COUNTIF('chamadas_22-04-2026_165407'!L:L,Planilha1!A2) -> 8
A3: Fora de Area / Cx de Mensagens | B3: Tentativa | C3: =COUNTIF('chamadas_22-04-2026_165407'!L:L,Planilha1!A3) -> 2291 | E3: Tentativa | F3: =SUMIF(B:B,E3,C:C) -> 2856
A4: Não Atendeu | B4: Tentativa | C4: =COUNTIF('chamadas_22-04-2026_165407'!L:L,Planilha1!A4) -> 421 | E4: Interessado | F4: =SUMIF(B:B,E4,C:C) -> 140
A5: Enviar E-mail | B5: Interessado | C5: =COUNTIF('chamadas_22-04-2026_165407'!L:L,Planilha1!A5) -> 140 | E5: Alo | F5: =SUMIF(B:B,E5,C:C) -> 41
A6: Tel Não Atende / Ocupado | B6: Tentativa | C6: =COUNTIF('chamadas_22-04-2026_165407'!L:L,Planilha1!A6) -> 68 | E6: Contato com o Decisor | F6: =SUMIF(B:B,E6,C:C) -> 41
A7: Ocupado | B7: Tentativa | C7: =COUNTIF('chamadas_22-04-2026_165407'!L:L,Planilha1!A7) -> 37 | F7: =SUM(F3:F6) -> 3078
A8: Retornar | B8: Alo | C8: =COUNTIF('chamadas_22-04-2026_165407'!L:L,Planilha1!A8) -> 21 | G8: 3225
A9: Formulário Preenchido | B9: Contato com o Decisor | C9: =COUNTIF('chamadas_22-04-2026_165407'!L:L,Planilha1!A9) -> 7
A10: INFORMADO | B10: Contato com o Decisor | C10: =COUNTIF('chamadas_22-04-2026_165407'!L:L,Planilha1!A10) -> 25
A11: Recado | B11: Alo | C11: =COUNTIF('chamadas_22-04-2026_165407'!L:L,Planilha1!A11) -> 1 | F11: 516
A12: Não tem interesse | B12: Contato com o Decisor | C12: =COUNTIF('chamadas_22-04-2026_165407'!L:L,Planilha1!A12) -> 9
A13: Cliente Desligou | B13: Alo | C13: =COUNTIF('chamadas_22-04-2026_165407'!L:L,Planilha1!A13) -> 10
A14: Ligação Muda | B14: Tentativa | C14: =COUNTIF('chamadas_22-04-2026_165407'!L:L,Planilha1!A14) -> 39
A15: Contato Indisponível | B15: Alo | C15: =COUNTIF('chamadas_22-04-2026_165407'!L:L,Planilha1!A15) -> 1
